
"smart_sources:Хранилище/-/Языки программирования/Python/Учебник из сайта/Python. Урок 8. Работа с исключениями.md": {"path":"Хранилище/-/Языки программирования/Python/Учебник из сайта/Python. Урок 8. Работа с исключениями.md","last_embed":{"hash":null},"embeddings":{},"last_read":{"hash":"wbxu99","at":1760991546270},"class_name":"SmartSource","last_import":{"mtime":1760991534671,"size":17958,"at":1760991546272,"hash":"wbxu99"},"blocks":{"#":[1,1],"#Уроки_Python":[2,2],"#Исключения в языках программирования":[3,12],"#Исключения в языках программирования#{1}":[5,12],"#Ошибки и исключения в Python":[13,48],"#Ошибки и исключения в Python#{1}":[15,16],"#Ошибки и исключения в Python#Синтаксические ошибки в Python":[17,30],"#Ошибки и исключения в Python#Синтаксические ошибки в Python#{1}":[19,30],"#Ошибки и исключения в Python#Исключения в Python":[31,48],"#Ошибки и исключения в Python#Исключения в Python#{1}":[33,48],"#Иерархия исключений в Python":[49,120],"#Иерархия исключений в Python#{1}":[51,120],"#Обработка исключений в Python":[121,220],"#Обработка исключений в Python#{1}":[123,220],"#Использование finally в обработке исключений":[221,251],"#Использование finally в обработке исключений#{1}":[223,251],"#Генерация исключений в Python":[252,266],"#Генерация исключений в Python#{1}":[254,266],"#Пользовательские исключения (User-defined Exceptions) в Python":[267,288],"#Пользовательские исключения (User-defined Exceptions) в Python#{1}":[269,288]},"outlinks":[{"title":"здесь","target":"https://docs.python.org/3/library/exceptions.html#bltin-exceptions","line":120},{"title":"следующим образом","target":"https://docs.python.org/3/tutorial/errors.html","line":165}],"metadata":{"tags":["#Уроки_Python"]},"task_lines":[]},